[2025-07-06T20:35:21.528+0000] {local_task_job_runner.py:123} INFO - ::group::Pre task execution logs
[2025-07-06T20:35:21.547+0000] {taskinstance.py:2614} INFO - Dependencies all met for dep_context=non-requeueable deps ti=<TaskInstance: etl_dag_datos_potencia.ETL.cargar_demandas_maximas manual__2025-07-06T20:35:15.171731+00:00 [queued]>
[2025-07-06T20:35:21.555+0000] {taskinstance.py:2614} INFO - Dependencies all met for dep_context=requeueable deps ti=<TaskInstance: etl_dag_datos_potencia.ETL.cargar_demandas_maximas manual__2025-07-06T20:35:15.171731+00:00 [queued]>
[2025-07-06T20:35:21.556+0000] {taskinstance.py:2867} INFO - Starting attempt 1 of 1
[2025-07-06T20:35:21.568+0000] {taskinstance.py:2890} INFO - Executing <Task(PythonOperator): ETL.cargar_demandas_maximas> on 2025-07-06 20:35:15.171731+00:00
[2025-07-06T20:35:21.577+0000] {warnings.py:112} WARNING - /home/***/.local/lib/python3.12/site-packages/***/task/task_runner/standard_task_runner.py:70: DeprecationWarning: This process (pid=304) is multi-threaded, use of fork() may lead to deadlocks in the child.
  pid = os.fork()

[2025-07-06T20:35:21.579+0000] {standard_task_runner.py:72} INFO - Started process 309 to run task
[2025-07-06T20:35:21.580+0000] {standard_task_runner.py:104} INFO - Running: ['***', 'tasks', 'run', 'etl_dag_datos_potencia', 'ETL.cargar_demandas_maximas', 'manual__2025-07-06T20:35:15.171731+00:00', '--job-id', '16', '--raw', '--subdir', 'DAGS_FOLDER/potencia_etl_dag.py', '--cfg-path', '/tmp/tmpalo134ow']
[2025-07-06T20:35:21.582+0000] {standard_task_runner.py:105} INFO - Job 16: Subtask ETL.cargar_demandas_maximas
[2025-07-06T20:35:21.637+0000] {task_command.py:467} INFO - Running <TaskInstance: etl_dag_datos_potencia.ETL.cargar_demandas_maximas manual__2025-07-06T20:35:15.171731+00:00 [running]> on host b7670b46f5dc
[2025-07-06T20:35:21.710+0000] {taskinstance.py:3134} INFO - Exporting env vars: AIRFLOW_CTX_DAG_OWNER='***' AIRFLOW_CTX_DAG_ID='etl_dag_datos_potencia' AIRFLOW_CTX_TASK_ID='ETL.cargar_demandas_maximas' AIRFLOW_CTX_EXECUTION_DATE='2025-07-06T20:35:15.171731+00:00' AIRFLOW_CTX_TRY_NUMBER='1' AIRFLOW_CTX_DAG_RUN_ID='manual__2025-07-06T20:35:15.171731+00:00'
[2025-07-06T20:35:21.711+0000] {taskinstance.py:732} INFO - ::endgroup::
[2025-07-06T20:35:24.707+0000] {taskinstance.py:3313} ERROR - Task failed with exception
Traceback (most recent call last):
  File "/home/airflow/.local/lib/python3.12/site-packages/airflow/models/taskinstance.py", line 768, in _execute_task
    result = _execute_callable(context=context, **execute_callable_kwargs)
             ^^^^^^^^^^^^^^^^^^^^^^^^^^^^^^^^^^^^^^^^^^^^^^^^^^^^^^^^^^^^^
  File "/home/airflow/.local/lib/python3.12/site-packages/airflow/models/taskinstance.py", line 734, in _execute_callable
    return ExecutionCallableRunner(
           ^^^^^^^^^^^^^^^^^^^^^^^^
  File "/home/airflow/.local/lib/python3.12/site-packages/airflow/utils/operator_helpers.py", line 252, in run
    return self.func(*args, **kwargs)
           ^^^^^^^^^^^^^^^^^^^^^^^^^^
  File "/home/airflow/.local/lib/python3.12/site-packages/airflow/models/baseoperator.py", line 424, in wrapper
    return func(self, *args, **kwargs)
           ^^^^^^^^^^^^^^^^^^^^^^^^^^^
  File "/home/airflow/.local/lib/python3.12/site-packages/airflow/operators/python.py", line 238, in execute
    return_value = self.execute_callable()
                   ^^^^^^^^^^^^^^^^^^^^^^^
  File "/home/airflow/.local/lib/python3.12/site-packages/airflow/operators/python.py", line 256, in execute_callable
    return runner.run(*self.op_args, **self.op_kwargs)
           ^^^^^^^^^^^^^^^^^^^^^^^^^^^^^^^^^^^^^^^^^^^
  File "/home/airflow/.local/lib/python3.12/site-packages/airflow/utils/operator_helpers.py", line 252, in run
    return self.func(*args, **kwargs)
           ^^^^^^^^^^^^^^^^^^^^^^^^^^
  File "/opt/airflow/dags/potencia_etl_dag.py", line 56, in cargar_demandas_maximas
    db_cliente.potencia.mediciones_max_anuales.delete_many({})
  File "/home/airflow/.local/lib/python3.12/site-packages/pymongo/synchronous/collection.py", line 1711, in delete_many
    self._delete_retryable(
  File "/home/airflow/.local/lib/python3.12/site-packages/pymongo/synchronous/collection.py", line 1587, in _delete_retryable
    return self._database.client._retryable_write(
           ^^^^^^^^^^^^^^^^^^^^^^^^^^^^^^^^^^^^^^^
  File "/home/airflow/.local/lib/python3.12/site-packages/pymongo/synchronous/mongo_client.py", line 2061, in _retryable_write
    return self._retry_with_session(retryable, func, s, bulk, operation, operation_id)
           ^^^^^^^^^^^^^^^^^^^^^^^^^^^^^^^^^^^^^^^^^^^^^^^^^^^^^^^^^^^^^^^^^^^^^^^^^^^
  File "/home/airflow/.local/lib/python3.12/site-packages/pymongo/synchronous/mongo_client.py", line 1947, in _retry_with_session
    return self._retry_internal(
           ^^^^^^^^^^^^^^^^^^^^^
  File "/home/airflow/.local/lib/python3.12/site-packages/pymongo/_csot.py", line 125, in csot_wrapper
    return func(self, *args, **kwargs)
           ^^^^^^^^^^^^^^^^^^^^^^^^^^^
  File "/home/airflow/.local/lib/python3.12/site-packages/pymongo/synchronous/mongo_client.py", line 1993, in _retry_internal
    ).run()
      ^^^^^
  File "/home/airflow/.local/lib/python3.12/site-packages/pymongo/synchronous/mongo_client.py", line 2730, in run
    return self._read() if self._is_read else self._write()
                                              ^^^^^^^^^^^^^
  File "/home/airflow/.local/lib/python3.12/site-packages/pymongo/synchronous/mongo_client.py", line 2841, in _write
    with self._client._checkout(self._server, self._session) as conn:
         ^^^^^^^^^^^^^^^^^^^^^^^^^^^^^^^^^^^^^^^^^^^^^^^^^^^
  File "/usr/local/lib/python3.12/contextlib.py", line 137, in __enter__
    return next(self.gen)
           ^^^^^^^^^^^^^^
  File "/home/airflow/.local/lib/python3.12/site-packages/pymongo/synchronous/mongo_client.py", line 1756, in _checkout
    with server.checkout(handler=err_handler) as conn:
         ^^^^^^^^^^^^^^^^^^^^^^^^^^^^^^^^^^^^
  File "/usr/local/lib/python3.12/contextlib.py", line 137, in __enter__
    return next(self.gen)
           ^^^^^^^^^^^^^^
  File "/home/airflow/.local/lib/python3.12/site-packages/pymongo/synchronous/pool.py", line 1119, in checkout
    conn = self._get_conn(checkout_started_time, handler=handler)
           ^^^^^^^^^^^^^^^^^^^^^^^^^^^^^^^^^^^^^^^^^^^^^^^^^^^^^^
  File "/home/airflow/.local/lib/python3.12/site-packages/pymongo/synchronous/pool.py", line 1281, in _get_conn
    conn = self.connect(handler=handler)
           ^^^^^^^^^^^^^^^^^^^^^^^^^^^^^
  File "/home/airflow/.local/lib/python3.12/site-packages/pymongo/synchronous/pool.py", line 1073, in connect
    conn.authenticate()
  File "/home/airflow/.local/lib/python3.12/site-packages/pymongo/synchronous/pool.py", line 526, in authenticate
    auth.authenticate(creds, self, reauthenticate=reauthenticate)
  File "/home/airflow/.local/lib/python3.12/site-packages/pymongo/synchronous/auth.py", line 450, in authenticate
    auth_func(credentials, conn)
  File "/home/airflow/.local/lib/python3.12/site-packages/pymongo/synchronous/auth.py", line 355, in _authenticate_default
    return _authenticate_scram(credentials, conn, "SCRAM-SHA-1")
           ^^^^^^^^^^^^^^^^^^^^^^^^^^^^^^^^^^^^^^^^^^^^^^^^^^^^^
  File "/home/airflow/.local/lib/python3.12/site-packages/pymongo/synchronous/auth.py", line 96, in _authenticate_scram
    res = conn.command(source, cmd)
          ^^^^^^^^^^^^^^^^^^^^^^^^^
  File "/home/airflow/.local/lib/python3.12/site-packages/pymongo/synchronous/helpers.py", line 47, in inner
    return func(*args, **kwargs)
           ^^^^^^^^^^^^^^^^^^^^^
  File "/home/airflow/.local/lib/python3.12/site-packages/pymongo/synchronous/pool.py", line 414, in command
    return command(
           ^^^^^^^^
  File "/home/airflow/.local/lib/python3.12/site-packages/pymongo/synchronous/network.py", line 212, in command
    helpers_shared._check_command_response(
  File "/home/airflow/.local/lib/python3.12/site-packages/pymongo/helpers_shared.py", line 250, in _check_command_response
    raise OperationFailure(errmsg, code, response, max_wire_version)
pymongo.errors.OperationFailure: bad auth : Authentication failed., full error: {'ok': 0, 'errmsg': 'bad auth : Authentication failed.', 'code': 8000, 'codeName': 'AtlasError'}
[2025-07-06T20:35:24.721+0000] {taskinstance.py:1226} INFO - Marking task as FAILED. dag_id=etl_dag_datos_potencia, task_id=ETL.cargar_demandas_maximas, run_id=manual__2025-07-06T20:35:15.171731+00:00, execution_date=20250706T203515, start_date=20250706T203521, end_date=20250706T203524
[2025-07-06T20:35:24.747+0000] {taskinstance.py:341} INFO - ::group::Post task execution logs
[2025-07-06T20:35:24.748+0000] {standard_task_runner.py:124} ERROR - Failed to execute job 16 for task ETL.cargar_demandas_maximas (bad auth : Authentication failed., full error: {'ok': 0, 'errmsg': 'bad auth : Authentication failed.', 'code': 8000, 'codeName': 'AtlasError'}; 309)
Traceback (most recent call last):
  File "/home/airflow/.local/lib/python3.12/site-packages/airflow/task/task_runner/standard_task_runner.py", line 117, in _start_by_fork
    ret = args.func(args, dag=self.dag)
          ^^^^^^^^^^^^^^^^^^^^^^^^^^^^^
  File "/home/airflow/.local/lib/python3.12/site-packages/airflow/cli/cli_config.py", line 49, in command
    return func(*args, **kwargs)
           ^^^^^^^^^^^^^^^^^^^^^
  File "/home/airflow/.local/lib/python3.12/site-packages/airflow/utils/cli.py", line 116, in wrapper
    return f(*args, **kwargs)
           ^^^^^^^^^^^^^^^^^^
  File "/home/airflow/.local/lib/python3.12/site-packages/airflow/cli/commands/task_command.py", line 483, in task_run
    task_return_code = _run_task_by_selected_method(args, _dag, ti)
                       ^^^^^^^^^^^^^^^^^^^^^^^^^^^^^^^^^^^^^^^^^^^^
  File "/home/airflow/.local/lib/python3.12/site-packages/airflow/cli/commands/task_command.py", line 256, in _run_task_by_selected_method
    return _run_raw_task(args, ti)
           ^^^^^^^^^^^^^^^^^^^^^^^
  File "/home/airflow/.local/lib/python3.12/site-packages/airflow/cli/commands/task_command.py", line 341, in _run_raw_task
    return ti._run_raw_task(
           ^^^^^^^^^^^^^^^^^
  File "/home/airflow/.local/lib/python3.12/site-packages/airflow/utils/session.py", line 97, in wrapper
    return func(*args, session=session, **kwargs)
           ^^^^^^^^^^^^^^^^^^^^^^^^^^^^^^^^^^^^^^
  File "/home/airflow/.local/lib/python3.12/site-packages/airflow/models/taskinstance.py", line 3006, in _run_raw_task
    return _run_raw_task(
           ^^^^^^^^^^^^^^
  File "/home/airflow/.local/lib/python3.12/site-packages/airflow/models/taskinstance.py", line 274, in _run_raw_task
    TaskInstance._execute_task_with_callbacks(
  File "/home/airflow/.local/lib/python3.12/site-packages/airflow/models/taskinstance.py", line 3161, in _execute_task_with_callbacks
    result = self._execute_task(context, task_orig)
             ^^^^^^^^^^^^^^^^^^^^^^^^^^^^^^^^^^^^^^
  File "/home/airflow/.local/lib/python3.12/site-packages/airflow/models/taskinstance.py", line 3185, in _execute_task
    return _execute_task(self, context, task_orig)
           ^^^^^^^^^^^^^^^^^^^^^^^^^^^^^^^^^^^^^^^
  File "/home/airflow/.local/lib/python3.12/site-packages/airflow/models/taskinstance.py", line 768, in _execute_task
    result = _execute_callable(context=context, **execute_callable_kwargs)
             ^^^^^^^^^^^^^^^^^^^^^^^^^^^^^^^^^^^^^^^^^^^^^^^^^^^^^^^^^^^^^
  File "/home/airflow/.local/lib/python3.12/site-packages/airflow/models/taskinstance.py", line 734, in _execute_callable
    return ExecutionCallableRunner(
           ^^^^^^^^^^^^^^^^^^^^^^^^
  File "/home/airflow/.local/lib/python3.12/site-packages/airflow/utils/operator_helpers.py", line 252, in run
    return self.func(*args, **kwargs)
           ^^^^^^^^^^^^^^^^^^^^^^^^^^
  File "/home/airflow/.local/lib/python3.12/site-packages/airflow/models/baseoperator.py", line 424, in wrapper
    return func(self, *args, **kwargs)
           ^^^^^^^^^^^^^^^^^^^^^^^^^^^
  File "/home/airflow/.local/lib/python3.12/site-packages/airflow/operators/python.py", line 238, in execute
    return_value = self.execute_callable()
                   ^^^^^^^^^^^^^^^^^^^^^^^
  File "/home/airflow/.local/lib/python3.12/site-packages/airflow/operators/python.py", line 256, in execute_callable
    return runner.run(*self.op_args, **self.op_kwargs)
           ^^^^^^^^^^^^^^^^^^^^^^^^^^^^^^^^^^^^^^^^^^^
  File "/home/airflow/.local/lib/python3.12/site-packages/airflow/utils/operator_helpers.py", line 252, in run
    return self.func(*args, **kwargs)
           ^^^^^^^^^^^^^^^^^^^^^^^^^^
  File "/opt/airflow/dags/potencia_etl_dag.py", line 56, in cargar_demandas_maximas
    db_cliente.potencia.mediciones_max_anuales.delete_many({})
  File "/home/airflow/.local/lib/python3.12/site-packages/pymongo/synchronous/collection.py", line 1711, in delete_many
    self._delete_retryable(
  File "/home/airflow/.local/lib/python3.12/site-packages/pymongo/synchronous/collection.py", line 1587, in _delete_retryable
    return self._database.client._retryable_write(
           ^^^^^^^^^^^^^^^^^^^^^^^^^^^^^^^^^^^^^^^
  File "/home/airflow/.local/lib/python3.12/site-packages/pymongo/synchronous/mongo_client.py", line 2061, in _retryable_write
    return self._retry_with_session(retryable, func, s, bulk, operation, operation_id)
           ^^^^^^^^^^^^^^^^^^^^^^^^^^^^^^^^^^^^^^^^^^^^^^^^^^^^^^^^^^^^^^^^^^^^^^^^^^^
  File "/home/airflow/.local/lib/python3.12/site-packages/pymongo/synchronous/mongo_client.py", line 1947, in _retry_with_session
    return self._retry_internal(
           ^^^^^^^^^^^^^^^^^^^^^
  File "/home/airflow/.local/lib/python3.12/site-packages/pymongo/_csot.py", line 125, in csot_wrapper
    return func(self, *args, **kwargs)
           ^^^^^^^^^^^^^^^^^^^^^^^^^^^
  File "/home/airflow/.local/lib/python3.12/site-packages/pymongo/synchronous/mongo_client.py", line 1993, in _retry_internal
    ).run()
      ^^^^^
  File "/home/airflow/.local/lib/python3.12/site-packages/pymongo/synchronous/mongo_client.py", line 2730, in run
    return self._read() if self._is_read else self._write()
                                              ^^^^^^^^^^^^^
  File "/home/airflow/.local/lib/python3.12/site-packages/pymongo/synchronous/mongo_client.py", line 2841, in _write
    with self._client._checkout(self._server, self._session) as conn:
         ^^^^^^^^^^^^^^^^^^^^^^^^^^^^^^^^^^^^^^^^^^^^^^^^^^^
  File "/usr/local/lib/python3.12/contextlib.py", line 137, in __enter__
    return next(self.gen)
           ^^^^^^^^^^^^^^
  File "/home/airflow/.local/lib/python3.12/site-packages/pymongo/synchronous/mongo_client.py", line 1756, in _checkout
    with server.checkout(handler=err_handler) as conn:
         ^^^^^^^^^^^^^^^^^^^^^^^^^^^^^^^^^^^^
  File "/usr/local/lib/python3.12/contextlib.py", line 137, in __enter__
    return next(self.gen)
           ^^^^^^^^^^^^^^
  File "/home/airflow/.local/lib/python3.12/site-packages/pymongo/synchronous/pool.py", line 1119, in checkout
    conn = self._get_conn(checkout_started_time, handler=handler)
           ^^^^^^^^^^^^^^^^^^^^^^^^^^^^^^^^^^^^^^^^^^^^^^^^^^^^^^
  File "/home/airflow/.local/lib/python3.12/site-packages/pymongo/synchronous/pool.py", line 1281, in _get_conn
    conn = self.connect(handler=handler)
           ^^^^^^^^^^^^^^^^^^^^^^^^^^^^^
  File "/home/airflow/.local/lib/python3.12/site-packages/pymongo/synchronous/pool.py", line 1073, in connect
    conn.authenticate()
  File "/home/airflow/.local/lib/python3.12/site-packages/pymongo/synchronous/pool.py", line 526, in authenticate
    auth.authenticate(creds, self, reauthenticate=reauthenticate)
  File "/home/airflow/.local/lib/python3.12/site-packages/pymongo/synchronous/auth.py", line 450, in authenticate
    auth_func(credentials, conn)
  File "/home/airflow/.local/lib/python3.12/site-packages/pymongo/synchronous/auth.py", line 355, in _authenticate_default
    return _authenticate_scram(credentials, conn, "SCRAM-SHA-1")
           ^^^^^^^^^^^^^^^^^^^^^^^^^^^^^^^^^^^^^^^^^^^^^^^^^^^^^
  File "/home/airflow/.local/lib/python3.12/site-packages/pymongo/synchronous/auth.py", line 96, in _authenticate_scram
    res = conn.command(source, cmd)
          ^^^^^^^^^^^^^^^^^^^^^^^^^
  File "/home/airflow/.local/lib/python3.12/site-packages/pymongo/synchronous/helpers.py", line 47, in inner
    return func(*args, **kwargs)
           ^^^^^^^^^^^^^^^^^^^^^
  File "/home/airflow/.local/lib/python3.12/site-packages/pymongo/synchronous/pool.py", line 414, in command
    return command(
           ^^^^^^^^
  File "/home/airflow/.local/lib/python3.12/site-packages/pymongo/synchronous/network.py", line 212, in command
    helpers_shared._check_command_response(
  File "/home/airflow/.local/lib/python3.12/site-packages/pymongo/helpers_shared.py", line 250, in _check_command_response
    raise OperationFailure(errmsg, code, response, max_wire_version)
pymongo.errors.OperationFailure: bad auth : Authentication failed., full error: {'ok': 0, 'errmsg': 'bad auth : Authentication failed.', 'code': 8000, 'codeName': 'AtlasError'}
[2025-07-06T20:35:24.803+0000] {local_task_job_runner.py:266} INFO - Task exited with return code 1
[2025-07-06T20:35:24.818+0000] {taskinstance.py:3901} INFO - 0 downstream tasks scheduled from follow-on schedule check
[2025-07-06T20:35:24.820+0000] {local_task_job_runner.py:245} INFO - ::endgroup::
